Workbook

Sheet README
A1: H.R. 1 Medicaid Coverage Loss and Life Expectancy by Arizona Legislative District
A2: Cornerstone Public Affairs — model workbook, September 4, 2026. Prepared for Brian.
A4: WHAT THIS IS
A5: Estimates, for each of Arizona's 30 legislative districts (2022 IRC map, used by both chambers), of (1) how many residents are projected to lose AHCCCS (Medicaid) coverage because of H.R. 1 (P.L. 119-21), (2) how many of them become uninsured, (3) the additional deaths per year that the peer-reviewed coverage-mortality literature implies, and (4) the resulting change in period life expectancy at birth, against a baseline built from CDC census-tract life expectancy (USALEEP) calibrated to the latest county figures.
A7: HOW TO READ THE NUMBERS (please read before quoting)
A8: • District figures are ALLOCATIONS of statewide projections (RAND for 2034; Urban Institute for the first full year; AHCCCS notice counts for the Oct. 2026 immigrant provision). AHCCCS publishes no enrollment by legislative district or ZIP code (HIPAA), so no district figure is an observed count. The allocation uses ACS 2020-2024 tract data on adults with Medicaid, calibrated to AHCCCS administrative enrollment by congressional district and county.
A9: • Two horizons: NEAR TERM = first full year of the Jan. 1, 2027 work requirement and six-month renewals (Urban Institute's 2028 projection) plus the Oct. 1, 2026 immigrant-eligibility change; FULL PHASE-IN = 2034, when the provider-tax and other provisions are fully in force (RAND).
A10: • Low / Central / High are a bounding ENVELOPE, not a statistical confidence interval: they combine the low and high ends of both the coverage-loss range and the mortality-effect range.
A11: • "Become uninsured" applies CBO's ratio of 7.8 million uninsured per 10.3 million fewer Medicaid enrollees (0.76). KFF's Arizona estimate of 290,000 newly uninsured by 2034 is higher than this model's 248,000, so the mortality results are conservative on this point.
A12: • Additional deaths per year are steady-state annual figures once coverage is lost (1.2 / 2.2 / 3.6 deaths per 1,000 uninsured person-years — Sommers et al. 2014; Gaffney et al. 2025 implied rate; Sommers 2017). The literature measures coverage GAINS; symmetric effects for losses are assumed, as every published projection of H.R. 1 does. Effects build over 3-4 years, so year-one deaths will be below steady state.
A13: • Life expectancy change is a PERIOD life-table shock: what life expectancy at birth in the district would be if the excess mortality persisted. It is not "years lost by each resident." The baseline is anchored to 2020-2022 county life expectancy (latest available), which embeds pandemic-period mortality, especially in Apache, Navajo and Gila counties (LDs 6 and 7).
A14: • Work-requirement losses exclude American Indians (exempt under Sec. 71119), consistent with RAND and Urban; six-month renewal losses do not (no exemption).
... A25: Assessment Inputs — rate schedule and statewide totals (ties to the CSPA one-pager: $1.80B payments lost, $565M assessment saved, $1.24B net per year at 3.5%; $9.9B net over FFY 2028-2037). Assessment by Facility — all 134 facilities in AHCCCS's SFY 2025 report with what each paid, received, and stands to lose, plus its legislative district. Assessment by System — the same rolled up by hospital system (e.g., Banner). Assessment by District — rolled up by the district where each facility sits.

Sheet District Results
A1: LD | B1: Main county | C1: 2020 population | D1: Adults 19-64 | E1: NEAR TERM: lose AHCCCS — Low | F1: NEAR TERM: lose AHCCCS — Central | G1: NEAR TERM: lose AHCCCS — High | H1: FULL PHASE-IN (2034): lose AHCCCS — Low | I1: FULL PHASE-IN: lose AHCCCS — Central | J1: FULL PHASE-IN: lose AHCCCS — High | K1: Full phase-in central as % of adults 19-64 | L1: Full phase-in central per 1,000 residents | M1: Full phase-in central excluding provider-tax component | N1: Become uninsured (full, central) | O1: Additional deaths per year (full) — Low | P1: Additional deaths per year (full) — Central | Q1: Additional deaths per year (full) — High | R1: Additional deaths per year (near term, central) | S1: Baseline life expectancy at birth (2020-22 calibrated) | T1: Life expectancy with H.R. 1 (full, central) | U1: Change (years) — Low | V1: Change (years) — Central | W1: Change (years) — High | X1: Change (months) — Central | Y1: Change (years) — near term, central
A2: 1 | B2: Yavapai | C2: ='Allocation Keys'!C2 | D2: ='Allocation Keys'!D2 | E2: =Assumptions!B2*'Allocation Keys'!F2+Assumptions!B3*'Allocation Keys'!G2+Assumptions!B4*'Allocation Keys'!K2 | F2: =Assumptions!C2*'Allocation Keys'!F2+Assumptions!C3*'Allocation Keys'!G2+Assumptions!C4*'Allocation Keys'!K2 | G2: =Assumptions!D2*'Allocation Keys'!F2+Assumptions!D3*'Allocation Keys'!G2+Assumptions!D4*'Allocation Keys'!K2 | H2: =Assumptions!B5*(Assumptions!B6*'Allocation Keys'!G2+Assumptions!B7*'Allocation Keys'!F2+Assumptions!B8*'Allocation Keys'!K2+Assumptions!B9*'Allocation Keys'!I2) | I2: =Assumptions!C5*(Assumptions!C6*'Allocation Keys'!G2+Assumptions!C7*'Allocation Keys'!F2+Assumptions!C8*'Allocation Keys'!K2+Assumptions!C9*'Allocation Keys'!I2) | J2: =Assumptions!D5*(Assumptions!D6*'Allocation Keys'!G2+Assumptions!D7*'Allocation Keys'!F2+Assumptions!D8*'Allocation Keys'!K2+Assumptions!D9*'Allocation Keys'!I2) | K2: =I2/D2 | L2: =I2/C2*1000 | M2: =I2-Assumptions!C5*Assumptions!C9*'Allocation Keys'!I2 | N2: =I2*Assumptions!C10 | O2: =H2*Assumptions!B10*Assumptions!B11/1000*'Allocation Keys'!Q2 | P2: =I2*Assumptions!C10*Assumptions!C11/1000*'Allocation Keys'!R2 | Q2: =J2*Assumptions!D10*Assumptions!D11/1000*'Allocation Keys'!S2 | R2: =F2*Assumptions!C10*Assumptions!C11/1000*'Allocation Keys'!R2 | S2: ='Life Expectancy'!F2 | T2: =S2+V2 | U2: =O2*-0.0083668 | V2: =P2*-0.00835543 | W2: =Q2*-0.00833549 | X2: =V2*12 | Y2: =R2*-0.00836229
A3: 2 | B3: Maricopa | C3: ='Allocation Keys'!C3 | D3: ='Allocation Keys'!D3 | E3: =Assumptions!B2*'Allocation Keys'!F3+Assumptions!B3*'Allocation Keys'!G3+Assumptions!B4*'Allocation Keys'!K3 | F3: =Assumptions!C2*'Allocation Keys'!F3+Assumptions!C3*'Allocation Keys'!G3+Assumptions!C4*'Allocation Keys'!K3 | G3: =Assumptions!D2*'Allocation Keys'!F3+Assumptions!D3*'Allocation Keys'!G3+Assumptions!D4*'Allocation Keys'!K3 | H3: =Assumptions!B5*(Assumptions!B6*'Allocation Keys'!G3+Assumptions!B7*'Allocation Keys'!F3+Assumptions!B8*'Allocation Keys'!K3+Assumptions!B9*'Allocation Keys'!I3) | I3: =Assumptions!C5*(Assumptions!C6*'Allocation Keys'!G3+Assumptions!C7*'Allocation Keys'!F3+Assumptions!C8*'Allocation Keys'!K3+Assumptions!C9*'Allocation Keys'!I3) | J3: =Assumptions!D5*(Assumptions!D6*'Allocation Keys'!G3+Assumptions!D7*'Allocation Keys'!F3+Assumptions!D8*'Allocation Keys'!K3+Assumptions!D9*'Allocation Keys'!I3) | K3: =I3/D3 | L3: =I3/C3*1000 | M3: =I3-Assumptions!C5*Assumptions!C9*'Allocation Keys'!I3 | N3: =I3*Assumptions!C10 | O3: =H3*Assumptions!B10*Assumptions!B11/1000*'Allocation Keys'!Q3 | P3: =I3*Assumptions!C10*Assumptions!C11/1000*'Allocation Keys'!R3 | Q3: =J3*Assumptions!D10*Assumptions!D11/1000*'Allocation Keys'!S3 | R3: =F3*Assumptions!C10*Assumptions!C11/1000*'Allocation Keys'!R3 | S3: ='Life Expectancy'!F3 | T3: =S3+V3 | U3: =O3*-0.00832313 | V3: =P3*-0.00831163 | W3: =Q3*-0.00829145 | X3: =V3*12 | Y3: =R3*-0.00831722
A4: 3 | B4: Maricopa | C4: ='Allocation Keys'!C4 | D4: ='Allocation Keys'!D4 | E4: =Assumptions!B2*'Allocation Keys'!F4+Assumptions!B3*'Allocation Keys'!G4+Assumptions!B4*'Allocation Keys'!K4 | F4: =Assumptions!C2*'Allocation Keys'!F4+Assumptions!C3*'Allocation Keys'!G4+Assumptions!C4*'Allocation Keys'!K4 | G4: =Assumptions!D2*'Allocation Keys'!F4+Assumptions!D3*'Allocation Keys'!G4+Assumptions!D4*'Allocation Keys'!K4 | H4: =Assumptions!B5*(Assumptions!B6*'Allocation Keys'!G4+Assumptions!B7*'Allocation Keys'!F4+Assumptions!B8*'Allocation Keys'!K4+Assumptions!B9*'Allocation Keys'!I4) | I4: =Assumptions!C5*(Assumptions!C6*'Allocation Keys'!G4+Assumptions!C7*'Allocation Keys'!F4+Assumptions!C8*'Allocation Keys'!K4+Assumptions!C9*'Allocation Keys'!I4) | J4: =Assumptions!D5*(Assumptions!D6*'Allocation Keys'!G4+Assumptions!D7*'Allocation Keys'!F4+Assumptions!D8*'Allocation Keys'!K4+Assumptions!D9*'Allocation Keys'!I4) | K4: =I4/D4 | L4: =I4/C4*1000 | M4: =I4-Assumptions!C5*Assumptions!C9*'Allocation Keys'!I4 | N4: =I4*Assumptions!C10 | O4: =H4*Assumptions!B10*Assumptions!B11/1000*'Allocation Keys'!Q4 | P4: =I4*Assumptions!C10*Assumptions!C11/1000*'Allocation Keys'!R4 | Q4: =J4*Assumptions!D10*Assumptions!D11/1000*'Allocation Keys'!S4 | R4: =F4*Assumptions!C10*Assumptions!C11/1000*'Allocation Keys'!R4 | S4: ='Life Expectancy'!F4 | T4: =S4+V4 | U4: =O4*-0.00981177 | V4: =P4*-0.00980735 | W4: =Q4*-0.00979957 | X4: =V4*12 | Y4: =R4*-0.00980886
A5: 4 | B5: Maricopa | C5: ='Allocation Keys'!C5 | D5: ='Allocation Keys'!D5 | E5: =Assumptions!B2*'Allocation Keys'!F5+Assumptions!B3*'Allocation Keys'!G5+Assumptions!B4*'Allocation Keys'!K5 | F5: =Assumptions!C2*'Allocation Keys'!F5+Assumptions!C3*'Allocation Keys'!G5+Assumptions!C4*'Allocation Keys'!K5 | G5: =Assumptions!D2*'Allocation Keys'!F5+Assumptions!D3*'Allocation Keys'!G5+Assumptions!D4*'Allocation Keys'!K5 | H5: =Assumptions!B5*(Assumptions!B6*'Allocation Keys'!G5+Assumptions!B7*'Allocation Keys'!F5+Assumptions!B8*'Allocation Keys'!K5+Assumptions!B9*'Allocation Keys'!I5) | I5: =Assumptions!C5*(Assumptions!C6*'Allocation Keys'!G5+Assumptions!C7*'Allocation Keys'!F5+Assumptions!C8*'Allocation Keys'!K5+Assumptions!C9*'Allocation Keys'!I5) | J5: =Assumptions!D5*(Assumptions!D6*'Allocation Keys'!G5+Assumptions!D7*'Allocation Keys'!F5+Assumptions!D8*'Allocation Keys'!K5+Assumptions!D9*'Allocation Keys'!I5) | K5: =I5/D5 | L5: =I5/C5*1000 | M5: =I5-Assumptions!C5*Assumptions!C9*'Allocation Keys'!I5 | N5: =I5*Assumptions!C10 | O5: =H5*Assumptions!B10*Assumptions!B11/1000*'Allocation Keys'!Q5 | P5: =I5*Assumptions!C10*Assumptions!C11/1000*'Allocation Keys'!R5 | Q5: =J5*Assumptions!D10*Assumptions!D11/1000*'Allocation Keys'!S5 | R5: =F5*Assumptions!C10*Assumptions!C11/1000*'Allocation Keys'!R5 | S5: ='Life Expectancy'!F5 | T5: =S5+V5 | U5: =O5*-0.00868436 | V5: =P5*-0.00867769 | W5: =Q5*-0.00866598 | X5: =V5*12 | Y5: =R5*-0.00868075
A6: 5 | B6: Maricopa | C6: ='Allocation Keys'!C6 | D6: ='Allocation Keys'!D6 | E6: =Assumptions!B2*'Allocation Keys'!F6+Assumptions!B3*'Allocation Keys'!G6+Assumptions!B4*'Allocation Keys'!K6 | F6: =Assumptions!C2*'Allocation Keys'!F6+Assumptions!C3*'Allocation Keys'!G6+Assumptions!C4*'Allocation Keys'!K6 | G6: =Assumptions!D2*'Allocation Keys'!F6+Assumptions!D3*'Allocation Keys'!G6+Assumptions!D4*'Allocation Keys'!K6 | H6: =Assumptions!B5*(Assumptions!B6*'Allocation Keys'!G6+Assumptions!B7*'Allocation Keys'!F6+Assumptions!B8*'Allocation Keys'!K6+Assumptions!B9*'Allocation Keys'!I6) | I6: =Assumptions!C5*(Assumptions!C6*'Allocation Keys'!G6+Assumptions!C7*'Allocation Keys'!F6+Assumptions!C8*'Allocation Keys'!K6+Assumptions!C9*'Allocation Keys'!I6) | J6: =Assumptions!D5*(Assumptions!D6*'Allocation Keys'!G6+Assumptions!D7*'Allocation Keys'!F6+Assumptions!D8*'Allocation Keys'!K6+Assumptions!D9*'Allocation Keys'!I6) | K6: =I6/D6 | L6: =I6/C6*1000 | M6: =I6-Assumptions!C5*Assumptions!C9*'Allocation Keys'!I6 | N6: =I6*Assumptions!C10 | O6: =H6*Assumptions!B10*Assumptions!B11/1000*'Allocation Keys'!Q6 | P6: =I6*Assumptions!C10*Assumptions!C11/1000*'Allocation Keys'!R6 | Q6: =J6*Assumptions!D10*Assumptions!D11/1000*'Allocation Keys'!S6 | R6: =F6*Assumptions!C10*Assumptions!C11/1000*'Allocation Keys'!R6 | S6: ='Life Expectancy'!F6 | T6: =S6+V6 | U6: =O6*-0.00828799 | V6: =P6*-0.0082744 | W6: =Q6*-0.00825055 | X6: =V6*12 | Y6: =R6*-0.00828218
A7: 6 | B7: Coconino | C7: ='Allocation Keys'!C7 | D7: ='Allocation Keys'!D7 | E7: =Assumptions!B2*'Allocation Keys'!F7+Assumptions!B3*'Allocation Keys'!G7+Assumptions!B4*'Allocation Keys'!K7 | F7: =Assumptions!C2*'Allocation Keys'!F7+Assumptions!C3*'Allocation Keys'!G7+Assumptions!C4*'Allocation Keys'!K7 | G7: =Assumptions!D2*'Allocation Keys'!F7+Assumptions!D3*'Allocation Keys'!G7+Assumptions!D4*'Allocation Keys'!K7 | H7: =Assumptions!B5*(Assumptions!B6*'Allocation Keys'!G7+Assumptions!B7*'Allocation Keys'!F7+Assumptions!B8*'Allocation Keys'!K7+Assumptions!B9*'Allocation Keys'!I7) | I7: =Assumptions!C5*(Assumptions!C6*'Allocation Keys'!G7+Assumptions!C7*'Allocation Keys'!F7+Assumptions!C8*'Allocation Keys'!K7+Assumptions!C9*'Allocation Keys'!I7) | J7: =Assumptions!D5*(Assumptions!D6*'Allocation Keys'!G7+Assumptions!D7*'Allocation Keys'!F7+Assumptions!D8*'Allocation Keys'!K7+Assumptions!D9*'Allocation Keys'!I7) | K7: =I7/D7 | L7: =I7/C7*1000 | M7: =I7-Assumptions!C5*Assumptions!C9*'Allocation Keys'!I7 | N7: =I7*Assumptions!C10 | O7: =H7*Assumptions!B10*Assumptions!B11/1000*'Allocation Keys'!Q7 | P7: =I7*Assumptions!C10*Assumptions!C11/1000*'Allocation Keys'!R7 | Q7: =J7*Assumptions!D10*Assumptions!D11/1000*'Allocation Keys'!S7 | R7: =F7*Assumptions!C10*Assumptions!C11/1000*'Allocation Keys'!R7 | S7: ='Life Expectancy'!F7 | T7: =S7+V7 | U7: =O7*-0.00788047 | V7: =P7*-0.00786818 | W7: =Q7*-0.00784661 | X7: =V7*12 | Y7: =R7*-0.00787468
A8: 7 | B8: Pinal | C8: ='Allocation Keys'!C8 | D8: ='Allocation Keys'!D8 | E8: =Assumptions!B2*'Allocation Keys'!F8+Assumptions!B3*'Allocation Keys'!G8+Assumptions!B4*'Allocation Keys'!K8 | F8: =Assumptions!C2*'Allocation Keys'!F8+Assumptions!C3*'Allocation Keys'!G8+Assumptions!C4*'Allocation Keys'!K8 | G8: =Assumptions!D2*'Allocation Keys'!F8+Assumptions!D3*'Allocation Keys'!G8+Assumptions!D4*'Allocation Keys'!K8 | H8: =Assumptions!B5*(Assumptions!B6*'Allocation Keys'!G8+Assumptions!B7*'Allocation Keys'!F8+Assumptions!B8*'Allocation Keys'!K8+Assumptions!B9*'Allocation Keys'!I8) | I8: =Assumptions!C5*(Assumptions!C6*'Allocation Keys'!G8+Assumptions!C7*'Allocation Keys'!F8+Assumptions!C8*'Allocation Keys'!K8+Assumptions!C9*'Allocation Keys'!I8) | J8: =Assumptions!D5*(Assumptions!D6*'Allocation Keys'!G8+Assumptions!D7*'Allocation Keys'!F8+Assumptions!D8*'Allocation Keys'!K8+Assumptions!D9*'Allocation Keys'!I8) | K8: =I8/D8 | L8: =I8/C8*1000 | M8: =I8-Assumptions!C5*Assumptions!C9*'Allocation Keys'!I8 | N8: =I8*Assumptions!C10 | O8: =H8*Assumptions!B10*Assumptions!B11/1000*'Allocation Keys'!Q8 | P8: =I8*Assumptions!C10*Assumptions!C11/1000*'Allocation Keys'!R8 | Q8: =J8*Assumptions!D10*Assumptions!D11/1000*'Allocation Keys'!S8 | R8: =F8*Assumptions!C10*Assumptions!C11/1000*'Allocation Keys'!R8 | S8: ='Life Expectancy'!F8 | T8: =S8+V8 | U8: =O8*-0.0087481 | V8: =P8*-0.00873584 | W8: =Q8*-0.00871431 | X8: =V8*12 | Y8: =R8*-0.00874291
A9: 8 | B9: Maricopa | C9: ='Allocation Keys'!C9 | D9: ='Allocation Keys'!D9 | E9: =Assumptions!B2*'Allocation Keys'!F9+Assumptions!B3*'Allocation Keys'!G9+Assumptions!B4*'Allocation Keys'!K9 | F9: =Assumptions!C2*'Allocation Keys'!F9+Assumptions!C3*'Allocation Keys'!G9+Assumptions!C4*'Allocation Keys'!K9 | G9: =Assumptions!D2*'Allocation Keys'!F9+Assumptions!D3*'Allocation Keys'!G9+Assumptions!D4*'Allocation Keys'!K9 | H9: =Assumptions!B5*(Assumptions!B6*'Allocation Keys'!G9+Assumptions!B7*'Allocation Keys'!F9+Assumptions!B8*'Allocation Keys'!K9+Assumptions!B9*'Allocation Keys'!I9) | I9: =Assumptions!C5*(Assumptions!C6*'Allocation Keys'!G9+Assumptions!C7*'Allocation Keys'!F9+Assumptions!C8*'Allocation Keys'!K9+Assumptions!C9*'Allocation Keys'!I9) | J9: =Assumptions!D5*(Assumptions!D6*'Allocation Keys'!G9+Assumptions!D7*'Allocation Keys'!F9+Assumptions!D8*'Allocation Keys'!K9+Assumptions!D9*'Allocation Keys'!I9) | K9: =I9/D9 | L9: =I9/C9*1000 | M9: =I9-Assumptions!C5*Assumptions!C9*'Allocation Keys'!I9 | N9: =I9*Assumptions!C10 | O9: =H9*Assumptions!B10*Assumptions!B11/1000*'Allocation Keys'!Q9 | P9: =I9*Assumptions!C10*Assumptions!C11/1000*'Allocation Keys'!R9 | Q9: =J9*Assumptions!D10*Assumptions!D11/1000*'Allocation Keys'!S9 | R9: =F9*Assumptions!C10*Assumptions!C11/1000*'Allocation Keys'!R9 | S9: ='Life Expectancy'!F9 | T9: =S9+V9 | U9: =O9*-0.00962387 | V9: =P9*-0.00961015 | W9: =Q9*-0.00958607 | X9: =V9*12 | Y9: =R9*-0.00961716
A10: 9 | B10: Maricopa | C10: ='Allocation Keys'!C10 | D10: ='Allocation Keys'!D10 | E10: =Assumptions!B2*'Allocation Keys'!F10+Assumptions!B3*'Allocation Keys'!G10+Assumptions!B4*'Allocation Keys'!K10 | F10: =Assumptions!C2*'Allocation Keys'!F10+Assumptions!C3*'Allocation Keys'!G10+Assumptions!C4*'Allocation Keys'!K10 | G10: =Assumptions!D2*'Allocation Keys'!F10+Assumptions!D3*'Allocation Keys'!G10+Assumptions!D4*'Allocation Keys'!K10 | H10: =Assumptions!B5*(Assumptions!B6*'Allocation Keys'!G10+Assumptions!B7*'Allocation Keys'!F10+Assumptions!B8*'Allocation Keys'!K10+Assumptions!B9*'Allocation Keys'!I10) | I10: =Assumptions!C5*(Assumptions!C6*'Allocation Keys'!G10+Assumptions!C7*'Allocation Keys'!F10+Assumptions!C8*'Allocation Keys'!K10+Assumptions!C9*'Allocation Keys'!I10) | J10: =Assumptions!D5*(Assumptions!D6*'Allocation Keys'!G10+Assumptions!D7*'Allocation Keys'!F10+Assumptions!D8*'Allocation Keys'!K10+Assumptions!D9*'Allocation Keys'!I10) | K10: =I10/D10 | L10: =I10/C10*1000 | M10: =I10-Assumptions!C5*Assumptions!C9*'Allocation Keys'!I10 | N10: =I10*Assumptions!C10 | O10: =H10*Assumptions!B10*Assumptions!B11/1000*'Allocation Keys'!Q10 | P10: =I10*Assumptions!C10*Assumptions!C11/1000*'Allocation Keys'!R10 | Q10: =J10*Assumptions!D10*Assumptions!D11/1000*'Allocation Keys'!S10 | R10: =F10*Assumptions!C10*Assumptions!C11/1000*'Allocation Keys'!R10 | S10: ='Life Expectancy'!F10 | T10: =S10+V10 | U10: =O10*-0.00959596 | V10: =P10*-0.00957996 | W10: =Q10*-0.00955188 | X10: =V10*12 | Y10: =R10*-0.0095895
A11: 10 | B11: Maricopa | C11: ='Allocation Keys'!C11 | D11: ='Allocation Keys'!D11 | E11: =Assumptions!B2*'Allocation Keys'!F11+Assumptions!B3*'Allocation Keys'!G11+Assumptions!B4*'Allocation Keys'!K11 | F11: =Assumptions!C2*'Allocation Keys'!F11+Assumptions!C3*'Allocation Keys'!G11+Assumptions!C4*'Allocation Keys'!K11 | G11: =Assumptions!D2*'Allocation Keys'!F11+Assumptions!D3*'Allocation Keys'!G11+Assumptions!D4*'Allocation Keys'!K11 | H11: =Assumptions!B5*(Assumptions!B6*'Allocation Keys'!G11+Assumptions!B7*'Allocation Keys'!F11+Assumptions!B8*'Allocation Keys'!K11+Assumptions!B9*'Allocation Keys'!I11) | I11: =Assumptions!C5*(Assumptions!C6*'Allocation Keys'!G11+Assumptions!C7*'Allocation Keys'!F11+Assumptions!C8*'Allocation Keys'!K11+Assumptions!C9*'Allocation Keys'!I11) | J11: =Assumptions!D5*(Assumptions!D6*'Allocation Keys'!G11+Assumptions!D7*'Allocation Keys'!F11+Assumptions!D8*'Allocation Keys'!K11+Assumptions!D9*'Allocation Keys'!I11) | K11: =I11/D11 | L11: =I11/C11*1000 | M11: =I11-Assumptions!C5*Assumptions!C9*'Allocation Keys'!I11 | N11: =I11*Assumptions!C10 | O11: =H11*Assumptions!B10*Assumptions!B11/1000*'Allocation Keys'!Q11 | P11: =I11*Assumptions!C10*Assumptions!C11/1000*'Allocation Keys'!R11 | Q11: =J11*Assumptions!D10*Assumptions!D11/1000*'Allocation Keys'!S11 | R11: =F11*Assumptions!C10*Assumptions!C11/1000*'Allocation Keys'!R11 | S11: ='Life Expectancy'!F11 | T11: =S11+V11 | U11: =O11*-0.008743 | V11: =P11*-0.00873295 | W11: =Q11*-0.00871529 | X11: =V11*12 | Y11: =R11*-0.0087384
A12: 11 | B12: Maricopa | C12: ='Allocation Keys'!C12 | D12: ='Allocation Keys'!D12 | E12: =Assumptions!B2*'Allocation Keys'!F12+Assumptions!B3*'Allocation Keys'!G12+Assumptions!B4*'Allocation Keys'!K12 | F12: =Assumptions!C2*'Allocation Keys'!F12+Assumptions!C3*'Allocation Keys'!G12+Assumptions!C4*'Allocation Keys'!K12 | G12: =Assumptions!D2*'Allocation Keys'!F12+Assumptions!D3*'Allocation Keys'!G12+Assumptions!D4*'Allocation Keys'!K12 | H12: =Assumptions!B5*(Assumptions!B6*'Allocation Keys'!G12+Assumptions!B7*'Allocation Keys'!F12+Assumptions!B8*'Allocation Keys'!K12+Assumptions!B9*'Allocation Keys'!I12) | I12: =Assumptions!C5*(Assumptions!C6*'Allocation Keys'!G12+Assumptions!C7*'Allocation Keys'!F12+Assumptions!C8*'Allocation Keys'!K12+Assumptions!C9*'Allocation Keys'!I12) | J12: =Assumptions!D5*(Assumptions!D6*'Allocation Keys'!G12+Assumptions!D7*'Allocation Keys'!F12+Assumptions!D8*'Allocation Keys'!K12+Assumptions!D9*'Allocation Keys'!I12) | K12: =I12/D12 | L12: =I12/C12*1000 | M12: =I12-Assumptions!C5*Assumptions!C9*'Allocation Keys'!I12 | N12: =I12*Assumptions!C10 | O12: =H12*Assumptions!B10*Assumptions!B11/1000*'Allocation Keys'!Q12 | P12: =I12*Assumptions!C10*Assumptions!C11/1000*'Allocation Keys'!R12 | Q12: =J12*Assumptions!D10*Assumptions!D11/1000*'Allocation Keys'!S12 | R12: =F12*Assumptions!C10*Assumptions!C11/1000*'Allocation Keys'!R12 | S12: ='Life Expectancy'!F12 | T12: =S12+V12 | U12: =O12*-0.00919463 | V12: =P12*-0.00917632 | W12: =Q12*-0.00914423 | X12: =V12*12 | Y12: =R12*-0.00918705
A13: 12 | B13: Maricopa | C13: ='Allocation Keys'!C13 | D13: ='Allocation Keys'!D13 | E13: =Assumptions!B2*'Allocation Keys'!F13+Assumptions!B3*'Allocation Keys'!G13+Assumptions!B4*'Allocation Keys'!K13 | F13: =Assumptions!C2*'Allocation Keys'!F13+Assumptions!C3*'Allocation Keys'!G13+Assumptions!C4*'Allocation Keys'!K13 | G13: =Assumptions!D2*'Allocation Keys'!F13+Assumptions!D3*'Allocation Keys'!G13+Assumptions!D4*'Allocation Keys'!K13 | H13: =Assumptions!B5*(Assumptions!B6*'Allocation Keys'!G13+Assumptions!B7*'Allocation Keys'!F13+Assumptions!B8*'Allocation Keys'!K13+Assumptions!B9*'Allocation Keys'!I13) | I13: =Assumptions!C5*(Assumptions!C6*'Allocation Keys'!G13+Assumptions!C7*'Allocation Keys'!F13+Assumptions!C8*'Allocation Keys'!K13+Assumptions!C9*'Allocation Keys'!I13) | J13: =Assumptions!D5*(Assumptions!D6*'Allocation Keys'!G13+Assumptions!D7*'Allocation Keys'!F13+Assumptions!D8*'Allocation Keys'!K13+Assumptions!D9*'Allocation Keys'!I13) | K13: =I13/D13 | L13: =I13/C13*1000 | M13: =I13-Assumptions!C5*Assumptions!C9*'Allocation Keys'!I13 | N13: =I13*Assumptions!C10 | O13: =H13*Assumptions!B10*Assumptions!B11/1000*'Allocation Keys'!Q13 | P13: =I13*Assumptions!C10*Assumptions!C11/1000*'Allocation Keys'!R13 | Q13: =J13*Assumptions!D10*Assumptions!D11/1000*'Allocation Keys'!S13 | R13: =F13*Assumptions!C10*Assumptions!C11/1000*'Allocation Keys'!R13 | S13: ='Life Expectancy'!F13 | T13: =S13+V13 | U13: =O13*-0.00915705 | V13: =P13*-0.00915048 | W13: =Q13*-0.00913894 | X13: =V13*12 | Y13: =R13*-0.00915379
A14: 13 | B14: Maricopa | C14: ='Allocation Keys'!C14 | D14: ='Allocation Keys'!D14 | E14: =Assumptions!B2*'Allocation Keys'!F14+Assumptions!B3*'Allocation Keys'!G14+Assumptions!B4*'Allocation Keys'!K14 | F14: =Assumptions!C2*'Allocation Keys'!F14+Assumptions!C3*'Allocation Keys'!G14+Assumptions!C4*'Allocation Keys'!K14 | G14: =Assumptions!D2*'Allocation Keys'!F14+Assumptions!D3*'Allocation Keys'!G14+Assumptions!D4*'Allocation Keys'!K14 | H14: =Assumptions!B5*(Assumptions!B6*'Allocation Keys'!G14+Assumptions!B7*'Allocation Keys'!F14+Assumptions!B8*'Allocation Keys'!K14+Assumptions!B9*'Allocation Keys'!I14) | I14: =Assumptions!C5*(Assumptions!C6*'Allocation Keys'!G14+Assumptions!C7*'Allocation Keys'!F14+Assumptions!C8*'Allocation Keys'!K14+Assumptions!C9*'Allocation Keys'!I14) | J14: =Assumptions!D5*(Assumptions!D6*'Allocation Keys'!G14+Assumptions!D7*'Allocation Keys'!F14+Assumptions!D8*'Allocation Keys'!K14+Assumptions!D9*'Allocation Keys'!I14) | K14: =I14/D14 | L14: =I14/C14*1000 | M14: =I14-Assumptions!C5*Assumptions!C9*'Allocation Keys'!I14 | N14: =I14*Assumptions!C10 | O14: =H14*Assumptions!B10*Assumptions!B11/1000*'Allocation Keys'!Q14 | P14: =I14*Assumptions!C10*Assumptions!C11/1000*'Allocation Keys'!R14 | Q14: =J14*Assumptions!D10*Assumptions!D11/1000*'Allocation Keys'!S14 | R14: =F14*Assumptions!C10*Assumptions!C11/1000*'Allocation Keys'!R14 | S14: ='Life Expectancy'!F14 | T14: =S14+V14 | U14: =O14*-0.00996349 | V14: =P14*-0.00995621 | W14: =Q14*-0.00994341 | X14: =V14*12 | Y14: =R14*-0.0099595
A15: 14 | B15: Maricopa | C15: ='Allocation Keys'!C15 | D15: ='Allocation Keys'!D15 | E15: =Assumptions!B2*'Allocation Keys'!F15+Assumptions!B3*'Allocation Keys'!G15+Assumptions!B4*'Allocation Keys'!K15 | F15: =Assumptions!C2*'Allocation Keys'!F15+Assumptions!C3*'Allocation Keys'!G15+Assumptions!C4*'Allocation Keys'!K15 | G15: =Assumptions!D2*'Allocation Keys'!F15+Assumptions!D3*'Allocation Keys'!G15+Assumptions!D4*'Allocation Keys'!K15 | H15: =Assumptions!B5*(Assumptions!B6*'Allocation Keys'!G15+Assumptions!B7*'Allocation Keys'!F15+Assumptions!B8*'Allocation Keys'!K15+Assumptions!B9*'Allocation Keys'!I15) | I15: =Assumptions!C5*(Assumptions!C6*'Allocation Keys'!G15+Assumptions!C7*'Allocation Keys'!F15+Assumptions!C8*'Allocation Keys'!K15+Assumptions!C9*'Allocation Keys'!I15) | J15: =Assumptions!D5*(Assumptions!D6*'Allocation Keys'!G15+Assumptions!D7*'Allocation Keys'!F15+Assumptions!D8*'Allocation Keys'!K15+Assumptions!D9*'Allocation Keys'!I15) | K15: =I15/D15 | L15: =I15/C15*1000 | M15: =I15-Assumptions!C5*Assumptions!C9*'Allocation Keys'!I15 | N15: =I15*Assumptions!C10 | O15: =H15*Assumptions!B10*Assumptions!B11/1000*'Allocation Keys'!Q15 | P15: =I15*Assumptions!C10*Assumptions!C11/1000*'Allocation Keys'!R15 | Q15: =J15*Assumptions!D10*Assumptions!D11/1000*'Allocation Keys'!S15 | R15: =F15*Assumptions!C10*Assumptions!C11/1000*'Allocation Keys'!R15 | S15: ='Life Expectancy'!F15 | T15: =S15+V15 | U15: =O15*-0.00980142 | V15: =P15*-0.00979558 | W15: =Q15*-0.00978531 | X15: =V15*12 | Y15: =R15*-0.00979832
A16: 15 | B16: Maricopa | C16: ='Allocation Keys'!C16 | D16: ='Allocation Keys'!D16 | E16: =Assumptions!B2*'Allocation Keys'!F16+Assumptions!B3*'Allocation Keys'!G16+Assumptions!B4*'Allocation Keys'!K16 | F16: =Assumptions!C2*'Allocation Keys'!F16+Assumptions!C3*'Allocation Keys'!G16+Assumptions!C4*'Allocation Keys'!K16 | G16: =Assumptions!D2*'Allocation Keys'!F16+Assumptions!D3*'Allocation Keys'!G16+Assumptions!D4*'Allocation Keys'!K16 | H16: =Assumptions!B5*(Assumptions!B6*'Allocation Keys'!G16+Assumptions!B7*'Allocation Keys'!F16+Assumptions!B8*'Allocation Keys'!K16+Assumptions!B9*'Allocation Keys'!I16) | I16: =Assumptions!C5*(Assumptions!C6*'Allocation Keys'!G16+Assumptions!C7*'Allocation Keys'!F16+Assumptions!C8*'Allocation Keys'!K16+Assumptions!C9*'Allocation Keys'!I16) | J16: =Assumptions!D5*(Assumptions!D6*'Allocation Keys'!G16+Assumptions!D7*'Allocation Keys'!F16+Assumptions!D8*'Allocation Keys'!K16+Assumptions!D9*'Allocation Keys'!I16) | K16: =I16/D16 | L16: =I16/C16*1000 | M16: =I16-Assumptions!C5*Assumptions!C9*'Allocation Keys'!I16 | N16: =I16*Assumptions!C10 | O16: =H16*Assumptions!B10*Assumptions!B11/1000*'Allocation Keys'!Q16 | P16: =I16*Assumptions!C10*Assumptions!C11/1000*'Allocation Keys'!R16 | Q16: =J16*Assumptions!D10*Assumptions!D11/1000*'Allocation Keys'!S16 | R16: =F16*Assumptions!C10*Assumptions!C11/1000*'Allocation Keys'!R16 | S16: ='Life Expectancy'!F16 | T16: =S16+V16 | U16: =O16*-0.00936631 | V16: =P16*-0.00935821 | W16: =Q16*-0.00934398 | X16: =V16*12 | Y16: =R16*-0.00936309
A17: 16 | B17: Pinal | C17: ='Allocation Keys'!C17 | D17: ='Allocation Keys'!D17 | E17: =Assumptions!B2*'Allocation Keys'!F17+Assumptions!B3*'Allocation Keys'!G17+Assumptions!B4*'Allocation Keys'!K17 | F17: =Assumptions!C2*'Allocation Keys'!F17+Assumptions!C3*'Allocation Keys'!G17+Assumptions!C4*'Allocation Keys'!K17 | G17: =Assumptions!D2*'Allocation Keys'!F17+Assumptions!D3*'Allocation Keys'!G17+Assumptions!D4*'Allocation Keys'!K17 | H17: =Assumptions!B5*(Assumptions!B6*'Allocation Keys'!G17+Assumptions!B7*'Allocation Keys'!F17+Assumptions!B8*'Allocation Keys'!K17+Assumptions!B9*'Allocation Keys'!I17) | I17: =Assumptions!C5*(Assumptions!C6*'Allocation Keys'!G17+Assumptions!C7*'Allocation Keys'!F17+Assumptions!C8*'Allocation Keys'!K17+Assumptions!C9*'Allocation Keys'!I17) | J17: =Assumptions!D5*(Assumptions!D6*'Allocation Keys'!G17+Assumptions!D7*'Allocation Keys'!F17+Assumptions!D8*'Allocation Keys'!K17+Assumptions!D9*'Allocation Keys'!I17) | K17: =I17/D17 | L17: =I17/C17*1000 | M17: =I17-Assumptions!C5*Assumptions!C9*'Allocation Keys'!I17 | N17: =I17*Assumptions!C10 | O17: =H17*Assumptions!B10*Assumptions!B11/1000*'Allocation Keys'!Q17 | P17: =I17*Assumptions!C10*Assumptions!C11/1000*'Allocation Keys'!R17 | Q17: =J17*Assumptions!D10*Assumptions!D11/1000*'Allocation Keys'!S17 | R17: =F17*Assumptions!C10*Assumptions!C11/1000*'Allocation Keys'!R17 | S17: ='Life Expectancy'!F17 | T17: =S17+V17 | U17: =O17*-0.00928222 | V17: =P17*-0.00926882 | W17: =Q17*-0.00924532 | X17: =V17*12 | Y17: =R17*-0.00927674
A18: 17 | B18: Pima | C18: ='Allocation Keys'!C18 | D18: ='Allocation Keys'!D18 | E18: =Assumptions!B2*'Allocation Keys'!F18+Assumptions!B3*'Allocation Keys'!G18+Assumptions!B4*'Allocation Keys'!K18 | F18: =Assumptions!C2*'Allocation Keys'!F18+Assumptions!C3*'Allocation Keys'!G18+Assumptions!C4*'Allocation Keys'!K18 | G18: =Assumptions!D2*'Allocation Keys'!F18+Assumptions!D3*'Allocation Keys'!G18+Assumptions!D4*'Allocation Keys'!K18 | H18: =Assumptions!B5*(Assumptions!B6*'Allocation Keys'!G18+Assumptions!B7*'Allocation Keys'!F18+Assumptions!B8*'Allocation Keys'!K18+Assumptions!B9*'Allocation Keys'!I18) | I18: =Assumptions!C5*(Assumptions!C6*'Allocation Keys'!G18+Assumptions!C7*'Allocation Keys'!F18+Assumptions!C8*'Allocation Keys'!K18+Assumptions!C9*'Allocation Keys'!I18) | J18: =Assumptions!D5*(Assumptions!D6*'Allocation Keys'!G18+Assumptions!D7*'Allocation Keys'!F18+Assumptions!D8*'Allocation Keys'!K18+Assumptions!D9*'Allocation Keys'!I18) | K18: =I18/D18 | L18: =I18/C18*1000 | M18: =I18-Assumptions!C5*Assumptions!C9*'Allocation Keys'!I18 | N18: =I18*Assumptions!C10 | O18: =H18*Assumptions!B10*Assumptions!B11/1000*'Allocation Keys'!Q18 | P18: =I18*Assumptions!C10*Assumptions!C11/1000*'Allocation Keys'!R18 | Q18: =J18*Assumptions!D10*Assumptions!D11/1000*'Allocation Keys'!S18 | R18: =F18*Assumptions!C10*Assumptions!C11/1000*'Allocation Keys'!R18 | S18: ='Life Expectancy'!F18 | T18: =S18+V18 | U18: =O18*-0.00981603 | V18: =P18*-0.00980728 | W18: =Q18*-0.00979191 | X18: =V18*12 | Y18: =R18*-0.00981233
A19: 18 | B19: Pima | C19: ='Allocation Keys'!C19 | D19: ='Allocation Keys'!D19 | E19: =Assumptions!B2*'Allocation Keys'!F19+Assumptions!B3*'Allocation Keys'!G19+Assumptions!B4*'Allocation Keys'!K19 | F19: =Assumptions!C2*'Allocation Keys'!F19+Assumptions!C3*'Allocation Keys'!G19+Assumptions!C4*'Allocation Keys'!K19 | G19: =Assumptions!D2*'Allocation Keys'!F19+Assumptions!D3*'Allocation Keys'!G19+Assumptions!D4*'Allocation Keys'!K19 | H19: =Assumptions!B5*(Assumptions!B6*'Allocation Keys'!G19+Assumptions!B7*'Allocation Keys'!F19+Assumptions!B8*'Allocation Keys'!K19+Assumptions!B9*'Allocation Keys'!I19) | I19: =Assumptions!C5*(Assumptions!C6*'Allocation Keys'!G19+Assumptions!C7*'Allocation Keys'!F19+Assumptions!C8*'Allocation Keys'!K19+Assumptions!C9*'Allocation Keys'!I19) | J19: =Assumptions!D5*(Assumptions!D6*'Allocation Keys'!G19+Assumptions!D7*'Allocation Keys'!F19+Assumptions!D8*'Allocation Keys'!K19+Assumptions!D9*'Allocation Keys'!I19) | K19: =I19/D19 | L19: =I19/C19*1000 | M19: =I19-Assumptions!C5*Assumptions!C9*'Allocation Keys'!I19 | N19: =I19*Assumptions!C10 | O19: =H19*Assumptions!B10*Assumptions!B11/1000*'Allocation Keys'!Q19 | P19: =I19*Assumptions!C10*Assumptions!C11/1000*'Allocation Keys'!R19 | Q19: =J19*Assumptions!D10*Assumptions!D11/1000*'Allocation Keys'!S19 | R19: =F19*Assumptions!C10*Assumptions!C11/1000*'Allocation Keys'!R19 | S19: ='Life Expectancy'!F19 | T19: =S19+V19 | U19: =O19*-0.00903863 | V19: =P19*-0.00902537 | W19: =Q19*-0.00900209 | X19: =V19*12 | Y19: =R19*-0.00903279
A20: 19 | B20: Cochise | C20: ='Allocation Keys'!C20 | D20: ='Allocation Keys'!D20 | E20: =Assumptions!B2*'Allocation Keys'!F20+Assumptions!B3*'Allocation Keys'!G20+Assumptions!B4*'Allocation Keys'!K20 | F20: =Assumptions!C2*'Allocation Keys'!F20+Assumptions!C3*'Allocation Keys'!G20+Assumptions!C4*'Allocation Keys'!K20 | G20: =Assumptions!D2*'Allocation Keys'!F20+Assumptions!D3*'Allocation Keys'!G20+Assumptions!D4*'Allocation Keys'!K20 | H20: =Assumptions!B5*(Assumptions!B6*'Allocation Keys'!G20+Assumptions!B7*'Allocation Keys'!F20+Assumptions!B8*'Allocation Keys'!K20+Assumptions!B9*'Allocation Keys'!I20) | I20: =Assumptions!C5*(Assumptions!C6*'Allocation Keys'!G20+Assumptions!C7*'Allocation Keys'!F20+Assumptions!C8*'Allocation Keys'!K20+Assumptions!C9*'Allocation Keys'!I20) | J20: =Assumptions!D5*(Assumptions!D6*'Allocation Keys'!G20+Assumptions!D7*'Allocation Keys'!F20+Assumptions!D8*'Allocation Keys'!K20+Assumptions!D9*'Allocation Keys'!I20) | K20: =I20/D20 | L20: =I20/C20*1000 | M20: =I20-Assumptions!C5*Assumptions!C9*'Allocation Keys'!I20 | N20: =I20*Assumptions!C10 | O20: =H20*Assumptions!B10*Assumptions!B11/1000*'Allocation Keys'!Q20 | P20: =I20*Assumptions!C10*Assumptions!C11/1000*'Allocation Keys'!R20 | Q20: =J20*Assumptions!D10*Assumptions!D11/1000*'Allocation Keys'!S20 | R20: =F20*Assumptions!C10*Assumptions!C11/1000*'Allocation Keys'!R20 | S20: ='Life Expectancy'!F20 | T20: =S20+V20 | U20: =O20*-0.01110737 | V20: =P20*-0.01108753 | W20: =Q20*-0.01105273 | X20: =V20*12 | Y20: =R20*-0.01109984
A21: 20 | B21: Pima | C21: ='Allocation Keys'!C21 | D21: ='Allocation Keys'!D21 | E21: =Assumptions!B2*'Allocation Keys'!F21+Assumptions!B3*'Allocation Keys'!G21+Assumptions!B4*'Allocation Keys'!K21 | F21: =Assumptions!C2*'Allocation Keys'!F21+Assumptions!C3*'Allocation Keys'!G21+Assumptions!C4*'Allocation Keys'!K21 | G21: =Assumptions!D2*'Allocation Keys'!F21+Assumptions!D3*'Allocation Keys'!G21+Assumptions!D4*'Allocation Keys'!K21 | H21: =Assumptions!B5*(Assumptions!B6*'Allocation Keys'!G21+Assumptions!B7*'Allocation Keys'!F21+Assumptions!B8*'Allocation Keys'!K21+Assumptions!B9*'Allocation Keys'!I21) | I21: =Assumptions!C5*(Assumptions!C6*'Allocation Keys'!G21+Assumptions!C7*'Allocation Keys'!F21+Assumptions!C8*'Allocation Keys'!K21+Assumptions!C9*'Allocation Keys'!I21) | J21: =Assumptions!D5*(Assumptions!D6*'Allocation Keys'!G21+Assumptions!D7*'Allocation Keys'!F21+Assumptions!D8*'Allocation Keys'!K21+Assumptions!D9*'Allocation Keys'!I21) | K21: =I21/D21 | L21: =I21/C21*1000 | M21: =I21-Assumptions!C5*Assumptions!C9*'Allocation Keys'!I21 | N21: =I21*Assumptions!C10 | O21: =H21*Assumptions!B10*Assumptions!B11/1000*'Allocation Keys'!Q21 | P21: =I21*Assumptions!C10*Assumptions!C11/1000*'Allocation Keys'!R21 | Q21: =J21*Assumptions!D10*Assumptions!D11/1000*'Allocation Keys'!S21 | R21: =F21*Assumptions!C10*Assumptions!C11/1000*'Allocation Keys'!R21 | S21: ='Life Expectancy'!F21 | T21: =S21+V21 | U21: =O21*-0.00958725 | V21: =P21*-0.0095656 | W21: =Q21*-0.00952765 | X21: =V21*12 | Y21: =R21*-0.00957895
A22: 21 | B22: Pima | C22: ='Allocation Keys'!C22 | D22: ='Allocation Keys'!D22 | E22: =Assumptions!B2*'Allocation Keys'!F22+Assumptions!B3*'Allocation Keys'!G22+Assumptions!B4*'Allocation Keys'!K22 | F22: =Assumptions!C2*'Allocation Keys'!F22+Assumptions!C3*'Allocation Keys'!G22+Assumptions!C4*'Allocation Keys'!K22 | G22: =Assumptions!D2*'Allocation Keys'!F22+Assumptions!D3*'Allocation Keys'!G22+Assumptions!D4*'Allocation Keys'!K22 | H22: =Assumptions!B5*(Assumptions!B6*'Allocation Keys'!G22+Assumptions!B7*'Allocation Keys'!F22+Assumptions!B8*'Allocation Keys'!K22+Assumptions!B9*'Allocation Keys'!I22) | I22: =Assumptions!C5*(Assumptions!C6*'Allocation Keys'!G22+Assumptions!C7*'Allocation Keys'!F22+Assumptions!C8*'Allocation Keys'!K22+Assumptions!C9*'Allocation Keys'!I22) | J22: =Assumptions!D5*(Assumptions!D6*'Allocation Keys'!G22+Assumptions!D7*'Allocation Keys'!F22+Assumptions!D8*'Allocation Keys'!K22+Assumptions!D9*'Allocation Keys'!I22) | K22: =I22/D22 | L22: =I22/C22*1000 | M22: =I22-Assumptions!C5*Assumptions!C9*'Allocation Keys'!I22 | N22: =I22*Assumptions!C10 | O22: =H22*Assumptions!B10*Assumptions!B11/1000*'Allocation Keys'!Q22 | P22: =I22*Assumptions!C10*Assumptions!C11/1000*'Allocation Keys'!R22 | Q22: =J22*Assumptions!D10*Assumptions!D11/1000*'Allocation Keys'!S22 | R22: =F22*Assumptions!C10*Assumptions!C11/1000*'Allocation Keys'!R22 | S22: ='Life Expectancy'!F22 | T22: =S22+V22 | U22: =O22*-0.00977367 | V22: =P22*-0.00975243 | W22: =Q22*-0.00971522 | X22: =V22*12 | Y22: =R22*-0.00976547
A23: 22 | B23: Maricopa | C23: ='Allocation Keys'!C23 | D23: ='Allocation Keys'!D23 | E23: =Assumptions!B2*'Allocation Keys'!F23+Assumptions!B3*'Allocation Keys'!G23+Assumptions!B4*'Allocation Keys'!K23 | F23: =Assumptions!C2*'Allocation Keys'!F23+Assumptions!C3*'Allocation Keys'!G23+Assumptions!C4*'Allocation Keys'!K23 | G23: =Assumptions!D2*'Allocation Keys'!F23+Assumptions!D3*'Allocation Keys'!G23+Assumptions!D4*'Allocation Keys'!K23 | H23: =Assumptions!B5*(Assumptions!B6*'Allocation Keys'!G23+Assumptions!B7*'Allocation Keys'!F23+Assumptions!B8*'Allocation Keys'!K23+Assumptions!B9*'Allocation Keys'!I23) | I23: =Assumptions!C5*(Assumptions!C6*'Allocation Keys'!G23+Assumptions!C7*'Allocation Keys'!F23+Assumptions!C8*'Allocation Keys'!K23+Assumptions!C9*'Allocation Keys'!I23) | J23: =Assumptions!D5*(Assumptions!D6*'Allocation Keys'!G23+Assumptions!D7*'Allocation Keys'!F23+Assumptions!D8*'Allocation Keys'!K23+Assumptions!D9*'Allocation Keys'!I23) | K23: =I23/D23 | L23: =I23/C23*1000 | M23: =I23-Assumptions!C5*Assumptions!C9*'Allocation Keys'!I23 | N23: =I23*Assumptions!C10 | O23: =H23*Assumptions!B10*Assumptions!B11/1000*'Allocation Keys'!Q23 | P23: =I23*Assumptions!C10*Assumptions!C11/1000*'Allocation Keys'!R23 | Q23: =J23*Assumptions!D10*Assumptions!D11/1000*'Allocation Keys'!S23 | R23: =F23*Assumptions!C10*Assumptions!C11/1000*'Allocation Keys'!R23 | S23: ='Life Expectancy'!F23 | T23: =S23+V23 | U23: =O23*-0.00901735 | V23: =P23*-0.00900199 | W23: =Q23*-0.00897505 | X23: =V23*12 | Y23: =R23*-0.00901126
A24: 23 | B24: Yuma | C24: ='Allocation Keys'!C24 | D24: ='Allocation Keys'!D24 | E24: =Assumptions!B2*'Allocation Keys'!F24+Assumptions!B3*'Allocation Keys'!G24+Assumptions!B4*'Allocation Keys'!K24 | F24: =Assumptions!C2*'Allocation Keys'!F24+Assumptions!C3*'Allocation Keys'!G24+Assumptions!C4*'Allocation Keys'!K24 | G24: =Assumptions!D2*'Allocation Keys'!F24+Assumptions!D3*'Allocation Keys'!G24+Assumptions!D4*'Allocation Keys'!K24 | H24: =Assumptions!B5*(Assumptions!B6*'Allocation Keys'!G24+Assumptions!B7*'Allocation Keys'!F24+Assumptions!B8*'Allocation Keys'!K24+Assumptions!B9*'Allocation Keys'!I24) | I24: =Assumptions!C5*(Assumptions!C6*'Allocation Keys'!G24+Assumptions!C7*'Allocation Keys'!F24+Assumptions!C8*'Allocation Keys'!K24+Assumptions!C9*'Allocation Keys'!I24) | J24: =Assumptions!D5*(Assumptions!D6*'Allocation Keys'!G24+Assumptions!D7*'Allocation Keys'!F24+Assumptions!D8*'Allocation Keys'!K24+Assumptions!D9*'Allocation Keys'!I24) | K24: =I24/D24 | L24: =I24/C24*1000 | M24: =I24-Assumptions!C5*Assumptions!C9*'Allocation Keys'!I24 | N24: =I24*Assumptions!C10 | O24: =H24*Assumptions!B10*Assumptions!B11/1000*'Allocation Keys'!Q24 | P24: =I24*Assumptions!C10*Assumptions!C11/1000*'Allocation Keys'!R24 | Q24: =J24*Assumptions!D10*Assumptions!D11/1000*'Allocation Keys'!S24 | R24: =F24*Assumptions!C10*Assumptions!C11/1000*'Allocation Keys'!R24 | S24: ='Life Expectancy'!F24 | T24: =S24+V24 | U24: =O24*-0.01038002 | V24: =P24*-0.01035873 | W24: =Q24*-0.01032141 | X24: =V24*12 | Y24: =R24*-0.01037203
A25: 24 | B25: Maricopa | C25: ='Allocation Keys'!C25 | D25: ='Allocation Keys'!D25 | E25: =Assumptions!B2*'Allocation Keys'!F25+Assumptions!B3*'Allocation Keys'!G25+Assumptions!B4*'Allocation Keys'!K25 | F25: =Assumptions!C2*'Allocation Keys'!F25+Assumptions!C3*'Allocation Keys'!G25+Assumptions!C4*'Allocation Keys'!K25 | G25: =Assumptions!D2*'Allocation Keys'!F25+Assumptions!D3*'Allocation Keys'!G25+Assumptions!D4*'Allocation Keys'!K25 | H25: =Assumptions!B5*(Assumptions!B6*'Allocation Keys'!G25+Assumptions!B7*'Allocation Keys'!F25+Assumptions!B8*'Allocation Keys'!K25+Assumptions!B9*'Allocation Keys'!I25) | I25: =Assumptions!C5*(Assumptions!C6*'Allocation Keys'!G25+Assumptions!C7*'Allocation Keys'!F25+Assumptions!C8*'Allocation Keys'!K25+Assumptions!C9*'Allocation Keys'!I25) | J25: =Assumptions!D5*(Assumptions!D6*'Allocation Keys'!G25+Assumptions!D7*'Allocation Keys'!F25+Assumptions!D8*'Allocation Keys'!K25+Assumptions!D9*'Allocation Keys'!I25) | K25: =I25/D25 | L25: =I25/C25*1000 | M25: =I25-Assumptions!C5*Assumptions!C9*'Allocation Keys'!I25 | N25: =I25*Assumptions!C10 | O25: =H25*Assumptions!B10*Assumptions!B11/1000*'Allocation Keys'!Q25 | P25: =I25*Assumptions!C10*Assumptions!C11/1000*'Allocation Keys'!R25 | Q25: =J25*Assumptions!D10*Assumptions!D11/1000*'Allocation Keys'!S25 | R25: =F25*Assumptions!C10*Assumptions!C11/1000*'Allocation Keys'!R25 | S25: ='Life Expectancy'!F25 | T25: =S25+V25 | U25: =O25*-0.00991382 | V25: =P25*-0.00988933 | W25: =Q25*-0.00984645 | X25: =V25*12 | Y25: =R25*-0.00990352
A26: 25 | B26: Maricopa | C26: ='Allocation Keys'!C26 | D26: ='Allocation Keys'!D26 | E26: =Assumptions!B2*'Allocation Keys'!F26+Assumptions!B3*'Allocation Keys'!G26+Assumptions!B4*'Allocation Keys'!K26 | F26: =Assumptions!C2*'Allocation Keys'!F26+Assumptions!C3*'Allocation Keys'!G26+Assumptions!C4*'Allocation Keys'!K26 | G26: =Assumptions!D2*'Allocation Keys'!F26+Assumptions!D3*'Allocation Keys'!G26+Assumptions!D4*'Allocation Keys'!K26 | H26: =Assumptions!B5*(Assumptions!B6*'Allocation Keys'!G26+Assumptions!B7*'Allocation Keys'!F26+Assumptions!B8*'Allocation Keys'!K26+Assumptions!B9*'Allocation Keys'!I26) | I26: =Assumptions!C5*(Assumptions!C6*'Allocation Keys'!G26+Assumptions!C7*'Allocation Keys'!F26+Assumptions!C8*'Allocation Keys'!K26+Assumptions!C9*'Allocation Keys'!I26) | J26: =Assumptions!D5*(Assumptions!D6*'Allocation Keys'!G26+Assumptions!D7*'Allocation Keys'!F26+Assumptions!D8*'Allocation Keys'!K26+Assumptions!D9*'Allocation Keys'!I26) | K26: =I26/D26 | L26: =I26/C26*1000 | M26: =I26-Assumptions!C5*Assumptions!C9*'Allocation Keys'!I26 | N26: =I26*Assumptions!C10 | O26: =H26*Assumptions!B10*Assumptions!B11/1000*'Allocation Keys'!Q26 | P26: =I26*Assumptions!C10*Assumptions!C11/1000*'Allocation Keys'!R26 | Q26: =J26*Assumptions!D10*Assumptions!D11/1000*'Allocation Keys'!S26 | R26: =F26*Assumptions!C10*Assumptions!C11/1000*'Allocation Keys'!R26 | S26: ='Life Expectancy'!F26 | T26: =S26+V26 | U26: =O26*-0.00981054 | V26: =P26*-0.00979661 | W26: =Q26*-0.00977217 | X26: =V26*12 | Y26: =R26*-0.00980428
A27: 26 | B27: Maricopa | C27: ='Allocation Keys'!C27 | D27: ='Allocation Keys'!D27 | E27: =Assumptions!B2*'Allocation Keys'!F27+Assumptions!B3*'Allocation Keys'!G27+Assumptions!B4*'Allocation Keys'!K27 | F27: =Assumptions!C2*'Allocation Keys'!F27+Assumptions!C3*'Allocation Keys'!G27+Assumptions!C4*'Allocation Keys'!K27 | G27: =Assumptions!D2*'Allocation Keys'!F27+Assumptions!D3*'Allocation Keys'!G27+Assumptions!D4*'Allocation Keys'!K27 | H27: =Assumptions!B5*(Assumptions!B6*'Allocation Keys'!G27+Assumptions!B7*'Allocation Keys'!F27+Assumptions!B8*'Allocation Keys'!K27+Assumptions!B9*'Allocation Keys'!I27) | I27: =Assumptions!C5*(Assumptions!C6*'Allocation Keys'!G27+Assumptions!C7*'Allocation Keys'!F27+Assumptions!C8*'Allocation Keys'!K27+Assumptions!C9*'Allocation Keys'!I27) | J27: =Assumptions!D5*(Assumptions!D6*'Allocation Keys'!G27+Assumptions!D7*'Allocation Keys'!F27+Assumptions!D8*'Allocation Keys'!K27+Assumptions!D9*'Allocation Keys'!I27) | K27: =I27/D27 | L27: =I27/C27*1000 | M27: =I27-Assumptions!C5*Assumptions!C9*'Allocation Keys'!I27 | N27: =I27*Assumptions!C10 | O27: =H27*Assumptions!B10*Assumptions!B11/1000*'Allocation Keys'!Q27 | P27: =I27*Assumptions!C10*Assumptions!C11/1000*'Allocation Keys'!R27 | Q27: =J27*Assumptions!D10*Assumptions!D11/1000*'Allocation Keys'!S27 | R27: =F27*Assumptions!C10*Assumptions!C11/1000*'Allocation Keys'!R27 | S27: ='Life Expectancy'!F27 | T27: =S27+V27 | U27: =O27*-0.00958228 | V27: =P27*-0.00955633 | W27: =Q27*-0.0095109 | X27: =V27*12 | Y27: =R27*-0.00956956
A28: 27 | B28: Maricopa | C28: ='Allocation Keys'!C28 | D28: ='Allocation Keys'!D28 | E28: =Assumptions!B2*'Allocation Keys'!F28+Assumptions!B3*'Allocation Keys'!G28+Assumptions!B4*'Allocation Keys'!K28 | F28: =Assumptions!C2*'Allocation Keys'!F28+Assumptions!C3*'Allocation Keys'!G28+Assumptions!C4*'Allocation Keys'!K28 | G28: =Assumptions!D2*'Allocation Keys'!F28+Assumptions!D3*'Allocation Keys'!G28+Assumptions!D4*'Allocation Keys'!K28 | H28: =Assumptions!B5*(Assumptions!B6*'Allocation Keys'!G28+Assumptions!B7*'Allocation Keys'!F28+Assumptions!B8*'Allocation Keys'!K28+Assumptions!B9*'Allocation Keys'!I28) | I28: =Assumptions!C5*(Assumptions!C6*'Allocation Keys'!G28+Assumptions!C7*'Allocation Keys'!F28+Assumptions!C8*'Allocation Keys'!K28+Assumptions!C9*'Allocation Keys'!I28) | J28: =Assumptions!D5*(Assumptions!D6*'Allocation Keys'!G28+Assumptions!D7*'Allocation Keys'!F28+Assumptions!D8*'Allocation Keys'!K28+Assumptions!D9*'Allocation Keys'!I28) | K28: =I28/D28 | L28: =I28/C28*1000 | M28: =I28-Assumptions!C5*Assumptions!C9*'Allocation Keys'!I28 | N28: =I28*Assumptions!C10 | O28: =H28*Assumptions!B10*Assumptions!B11/1000*'Allocation Keys'!Q28 | P28: =I28*Assumptions!C10*Assumptions!C11/1000*'Allocation Keys'!R28 | Q28: =J28*Assumptions!D10*Assumptions!D11/1000*'Allocation Keys'!S28 | R28: =F28*Assumptions!C10*Assumptions!C11/1000*'Allocation Keys'!R28 | S28: ='Life Expectancy'!F28 | T28: =S28+V28 | U28: =O28*-0.00870763 | V28: =P28*-0.00869489 | W28: =Q28*-0.00867254 | X28: =V28*12 | Y28: =R28*-0.00870183
A29: 28 | B29: Maricopa | C29: ='Allocation Keys'!C29 | D29: ='Allocation Keys'!D29 | E29: =Assumptions!B2*'Allocation Keys'!F29+Assumptions!B3*'Allocation Keys'!G29+Assumptions!B4*'Allocation Keys'!K29 | F29: =Assumptions!C2*'Allocation Keys'!F29+Assumptions!C3*'Allocation Keys'!G29+Assumptions!C4*'Allocation Keys'!K29 | G29: =Assumptions!D2*'Allocation Keys'!F29+Assumptions!D3*'Allocation Keys'!G29+Assumptions!D4*'Allocation Keys'!K29 | H29: =Assumptions!B5*(Assumptions!B6*'Allocation Keys'!G29+Assumptions!B7*'Allocation Keys'!F29+Assumptions!B8*'Allocation Keys'!K29+Assumptions!B9*'Allocation Keys'!I29) | I29: =Assumptions!C5*(Assumptions!C6*'Allocation Keys'!G29+Assumptions!C7*'Allocation Keys'!F29+Assumptions!C8*'Allocation Keys'!K29+Assumptions!C9*'Allocation Keys'!I29) | J29: =Assumptions!D5*(Assumptions!D6*'Allocation Keys'!G29+Assumptions!D7*'Allocation Keys'!F29+Assumptions!D8*'Allocation Keys'!K29+Assumptions!D9*'Allocation Keys'!I29) | K29: =I29/D29 | L29: =I29/C29*1000 | M29: =I29-Assumptions!C5*Assumptions!C9*'Allocation Keys'!I29 | N29: =I29*Assumptions!C10 | O29: =H29*Assumptions!B10*Assumptions!B11/1000*'Allocation Keys'!Q29 | P29: =I29*Assumptions!C10*Assumptions!C11/1000*'Allocation Keys'!R29 | Q29: =J29*Assumptions!D10*Assumptions!D11/1000*'Allocation Keys'!S29 | R29: =F29*Assumptions!C10*Assumptions!C11/1000*'Allocation Keys'!R29 | S29: ='Life Expectancy'!F29 | T29: =S29+V29 | U29: =O29*-0.01013992 | V29: =P29*-0.010131 | W29: =Q29*-0.01011532 | X29: =V29*12 | Y29: =R29*-0.01013511
A30: 29 | B30: Maricopa | C30: ='Allocation Keys'!C30 | D30: ='Allocation Keys'!D30 | E30: =Assumptions!B2*'Allocation Keys'!F30+Assumptions!B3*'Allocation Keys'!G30+Assumptions!B4*'Allocation Keys'!K30 | F30: =Assumptions!C2*'Allocation Keys'!F30+Assumptions!C3*'Allocation Keys'!G30+Assumptions!C4*'Allocation Keys'!K30 | G30: =Assumptions!D2*'Allocation Keys'!F30+Assumptions!D3*'Allocation Keys'!G30+Assumptions!D4*'Allocation Keys'!K30 | H30: =Assumptions!B5*(Assumptions!B6*'Allocation Keys'!G30+Assumptions!B7*'Allocation Keys'!F30+Assumptions!B8*'Allocation Keys'!K30+Assumptions!B9*'Allocation Keys'!I30) | I30: =Assumptions!C5*(Assumptions!C6*'Allocation Keys'!G30+Assumptions!C7*'Allocation Keys'!F30+Assumptions!C8*'Allocation Keys'!K30+Assumptions!C9*'Allocation Keys'!I30) | J30: =Assumptions!D5*(Assumptions!D6*'Allocation Keys'!G30+Assumptions!D7*'Allocation Keys'!F30+Assumptions!D8*'Allocation Keys'!K30+Assumptions!D9*'Allocation Keys'!I30) | K30: =I30/D30 | L30: =I30/C30*1000 | M30: =I30-Assumptions!C5*Assumptions!C9*'Allocation Keys'!I30 | N30: =I30*Assumptions!C10 | O30: =H30*Assumptions!B10*Assumptions!B11/1000*'Allocation Keys'!Q30 | P30: =I30*Assumptions!C10*Assumptions!C11/1000*'Allocation Keys'!R30 | Q30: =J30*Assumptions!D10*Assumptions!D11/1000*'Allocation Keys'!S30 | R30: =F30*Assumptions!C10*Assumptions!C11/1000*'Allocation Keys'!R30 | S30: ='Life Expectancy'!F30 | T30: =S30+V30 | U30: =O30*-0.00917811 | V30: =P30*-0.00916651 | W30: =Q30*-0.00914614 | X30: =V30*12 | Y30: =R30*-0.00917322
A31: 30 | B31: Mohave | C31: ='Allocation Keys'!C31 | D31: ='Allocation Keys'!D31 | E31: =Assumptions!B2*'Allocation Keys'!F31+Assumptions!B3*'Allocation Keys'!G31+Assumptions!B4*'Allocation Keys'!K31 | F31: =Assumptions!C2*'Allocation Keys'!F31+Assumptions!C3*'Allocation Keys'!G31+Assumptions!C4*'Allocation Keys'!K31 | G31: =Assumptions!D2*'Allocation Keys'!F31+Assumptions!D3*'Allocation Keys'!G31+Assumptions!D4*'Allocation Keys'!K31 | H31: =Assumptions!B5*(Assumptions!B6*'Allocation Keys'!G31+Assumptions!B7*'Allocation Keys'!F31+Assumptions!B8*'Allocation Keys'!K31+Assumptions!B9*'Allocation Keys'!I31) | I31: =Assumptions!C5*(Assumptions!C6*'Allocation Keys'!G31+Assumptions!C7*'Allocation Keys'!F31+Assumptions!C8*'Allocation Keys'!K31+Assumptions!C9*'Allocation Keys'!I31) | J31: =Assumptions!D5*(Assumptions!D6*'Allocation Keys'!G31+Assumptions!D7*'Allocation Keys'!F31+Assumptions!D8*'Allocation Keys'!K31+Assumptions!D9*'Allocation Keys'!I31) | K31: =I31/D31 | L31: =I31/C31*1000 | M31: =I31-Assumptions!C5*Assumptions!C9*'Allocation Keys'!I31 | N31: =I31*Assumptions!C10 | O31: =H31*Assumptions!B10*Assumptions!B11/1000*'Allocation Keys'!Q31 | P31: =I31*Assumptions!C10*Assumptions!C11/1000*'Allocation Keys'!R31 | Q31: =J31*Assumptions!D10*Assumptions!D11/1000*'Allocation Keys'!S31 | R31: =F31*Assumptions!C10*Assumptions!C11/1000*'Allocation Keys'!R31 | S31: ='Life Expectancy'!F31 | T31: =S31+V31 | U31: =O31*-0.00765604 | V31: =P31*-0.00764145 | W31: =Q31*-0.00761585 | X31: =V31*12 | Y31: =R31*-0.0076502
A32: Arizona | B32: statewide | C32: =SUM(C2:C31) | D32: =SUM(D2:D31) | E32: =SUM(E2:E31) | F32: =SUM(F2:F31) | G32: =SUM(G2:G31) | H32: =SUM(H2:H31) | I32: =SUM(I2:I31) | J32: =SUM(J2:J31) | K32: =I32/D32 | L32: =I32/C32*1000 | M32: =SUM(M2:M31) | N32: =SUM(N2:N31) | O32: =SUM(O2:O31) | P32: =SUM(P2:P31) | Q32: =SUM(Q2:Q31) | R32: =SUM(R2:R31) | S32: =SUMPRODUCT(S2:S31,C2:C31)/C32 | T32: =SUMPRODUCT(T2:T31,C2:C31)/C32 | U32: =SUMPRODUCT(U2:U31,C2:C31)/C32 | V32: =SUMPRODUCT(V2:V31,C2:C31)/C32 | W32: =SUMPRODUCT(W2:W31,C2:C31)/C32 | X32: =V32*12 | Y32: =SUMPRODUCT(Y2:Y31,C2:C31)/C32
A34: Near term = first full year after the Jan. 1, 2027 start of work requirements and six-month renewals (Urban Institute 2028 projection) plus the Oct. 1, 2026 immigrant-eligibility change. Full phase-in = 2034 (RAND). Low/Central/High is a bounding envelope. Deaths are steady-state annual figures. Life expectancy change is a period life-table effect (see README and Method & Caveats). Population-weighted statewide life expectancy values are shown in the Arizona row.

Sheet Assumptions
A1: Parameter | B1: Low | C1: Central | D1: High | E1: Units / population | F1: Source (see Sources sheet)
A2: NEAR TERM (first full year, 2028): six-month redeterminations, AZ expansion enrollment decline | B2: 56000 | C2: 91000 | D2: 91000 | E2: expansion adults (allocated by expansion-adult key) | F2: Urban Institute, Mar 25 2026, Appendix Table A.2 (high/medium/low mitigation) — https://www.urban.org/research/publication/projected-reductions-medicaid-expansion-enrollment-under-obbbas-work
A3: NEAR TERM: work requirement, incremental AZ expansion enrollment decline | B3: 67000 | C3: 106000 | D3: 155000 | E3: non-AIAN expansion adults (allocated by work-requirement key) | F3: Urban Institute, Mar 25 2026, Appendix Table A.2 (totals 123k / 197k / 246k, Table 3)
A4: NEAR TERM: Oct 1 2026 immigrant-eligibility provision (refugees, asylees, parolees) | B4: 11132 | C4: 22263 | D4: 34263 | E4: noncitizens with public coverage, excluding Mexico/Cuba/Haiti-born share | F4: AHCCCS advance notices: 22,263 (AzPHA Aug 31 2026). Low = half retain coverage; High = notices + ~12,000 SSI recipients under review
A5: FULL PHASE-IN (2034): total AZ Medicaid enrollment decline | B5: 248030.3 | C5: 327400 | D5: 406769.7 | E5: all enrollees; low/high = KFF/CBO band (250/330, 410/330) applied to RAND central | F5: RAND RRA4098-1-v2 (June 18 2026) Table B.15: -327,400; KFF Aug 20 2025 range
A6: share: work requirement (198.8k of 369.2k gross) | B6: 0.53846154 | C6: 0.53846154 | D6: 0.53846154 | E6: allocated by work-requirement key (AIAN excluded) | F6: RAND Table B.15 provision values, scaled to deduplicated total
A7: share: six-month redeterminations (65.7k) | B7: 0.17795233 | C7: 0.17795233 | D7: 0.17795233 | E7: allocated by expansion-adult key | F7: RAND Table B.15
A8: share: immigrant eligibility + emergency FMAP (5.0k + 2.3k) | B8: 0.019772481 | C8: 0.019772481 | D8: 0.019772481 | E8: allocated by noncitizen key | F8: RAND Table B.15
A9: share: provider-tax retrenchment + error-payment rule (94.2k + 3.2k) | B9: 0.26381365 | C9: 0.26381365 | D9: 0.26381365 | E9: allocated by adult (19-64) Medicaid key | F9: RAND Table B.15 (behavioral assumption: states trim optional eligibility as provider-tax revenue falls)
A10: Uninsured per person losing Medicaid enrollment | B10: 0.75728155 | C10: 0.75728155 | D10: 0.75728155 | E10: ratio | F10: CBO via KFF Jun 4 2025: 7.8M uninsured / 10.3M fewer enrollees (House bill). Enacted-law cross-check ~0.68 (KFF Feb 2026: -11M enrollees, +7.5M uninsured)
A11: Additional deaths per 1,000 uninsured person-years | B11: 1.2 | C11: 2.2 | D11: 3.6 | E11: deaths / 1,000 / year, adults 19-64 | F11: Low: Sommers, Long & Baicker 2014 (NNT 830). Central: Gaffney et al. 2025 implied (16,642/7.6M). High: Sommers 2017 (1 per 239-316)
A13: Calibration constant c (excess death rate of a person losing coverage ÷ Arizona age-specific death rate) | B13: 0.26504166 | C13: 0.48590971 | D13: 0.79512498 | E13: solved so statewide deaths per 1,000 uninsured equal the row above
A14: Note: near-term scenarios use the same death rates; c differs trivially (see assumptions.json).

Sheet Allocation Keys
A1: LD | B1: Main county | C1: 2020 population | D1: Adults 19-64 (ACS civ. noninst.) | E1: Expansion-adult key (calibrated count) | F1: Expansion-adult share | G1: Work-requirement key share (AIAN excluded) | H1: AIAN share of district expansion adults | I1: Adult (19-64) Medicaid key share | J1: Total Medicaid (all ages) key share | K1: Noncitizen (non-Mexico/Cuba/Haiti) public-coverage key share | L1: Age share 19-25 | M1: Age share 26-34 | N1: Age share 35-44 | O1: Age share 45-54 | P1: Age share 55-64 | Q1: Death-rate factor vs state (low) | R1: Death-rate factor (central) | S1: Death-rate factor (high)
A2: 1 | B2: Yavapai | C2: 237896 | D2: 120914 | E2: 12426.652 | F2: 0.026244284 | G2: 0.028313868 | H2: 0.040946688 | I2: 0.027213962 | J2: 0.027041639 | K2: 0.018813143 | L2: 0.11138458 | M2: 0.17210958 | N2: 0.16265221 | O2: 0.18034426 | P2: 0.37350936 | Q2: 1.2563173 | R2: 1.2563173 | S2: 1.2563173
A3: 2 | B3: Maricopa | C3: 246674 | D3: 159876 | E3: 16489.018 | F3: 0.034823736 | G3: 0.037260349 | H3: 0.048847788 | I3: 0.031941429 | J3: 0.031953256 | K3: 0.056766473 | L3: 0.1251577 | M3: 0.25850244 | N3: 0.20384734 | O3: 0.18999945 | P3: 0.22249306 | Q3: 0.9961552 | R3: 0.9961552 | S3: 0.9961552
A4: 3 | B4: Maricopa | C4: 236955 | D4: 125730 | E4: 4223.6725 | F4: 0.0089201223 | G4: 0.0094892322 | H4: 0.054329857 | I4: 0.0089902697 | J4: 0.010811207 | K4: 0.032548794 | L4: 0.1050948 | M4: 0.18029637 | N4: 0.17830112 | O4: 0.20373386 | P4: 0.33257384 | Q4: 1.2019897 | R4: 1.2019897 | S4: 1.2019897
A5: 4 | B5: Maricopa | C5: 244298 | D5: 146554 | E5: 8221.9863 | F5: 0.017364302 | G5: 0.018839894 | H5: 0.035506321 | I5: 0.015347771 | J5: 0.013689739 | K5: 0.03208145 | L5: 0.10316394 | M5: 0.18769124 | N5: 0.21793052 | O5: 0.1965691 | P5: 0.29464519 | Q5: 1.1381859 | R5: 1.1381859 | S5: 1.1381859
A6: 5 | B6: Maricopa | C6: 239088 | D6: 159734 | E6: 18566.09 | F6: 0.039210376 | G6: 0.040538174 | H6: 0.081299414 | I6: 0.040390859 | J6: 0.037578141 | K6: 0.040101309 | L6: 0.14020597 | M6: 0.25617104 | N6: 0.19869433 | O6: 0.18846875 | P6: 0.21645991 | Q6: 0.98015346 | R6: 0.98015346 | S6: 0.98015346
A7: 6 | B7: Coconino | C7: 225474 | D7: 125803 | E7: 30903.343 | F7: 0.065265856 | G7: 0.018948961 | H7: 0.74190617 | I7: 0.053675597 | J7: 0.050086375 | K7: 0.0098619278 | L7: 0.16894419 | M7: 0.23594162 | N7: 0.20600332 | O7: 0.16281266 | P7: 0.22629822 | Q7: 0.97757641 | R7: 0.97757641 | S7: 0.97757641
A8: 7 | B8: Pinal | C8: 240214 | D8: 128337 | E8: 13941.726 | F8: 0.02944402 | G8: 0.029522395 | H8: 0.10852114 | I8: 0.027381135 | J8: 0.028149325 | K8: 0.018680576 | L8: 0.15885086 | M8: 0.17619518 | N8: 0.18539407 | O8: 0.17479183 | P8: 0.30476806 | Q8: 1.1243253 | R8: 1.1243253 | S8: 1.1243253
A9: 8 | B9: Maricopa | C9: 244166 | D9: 181692 | E9: 16541.343 | F9: 0.034934244 | G9: 0.034046183 | H9: 0.13126631 | I9: 0.033869847 | J9: 0.030022708 | K9: 0.050146236 | L9: 0.21270505 | M9: 0.26342048 | N9: 0.19335877 | O9: 0.14372519 | P9: 0.18679052 | Q9: 0.88258369 | R9: 0.88258369 | S9: 0.88258369
A10: 9 | B10: Maricopa | C10: 238117 | D10: 147383 | E10: 18277.538 | F10: 0.038600973 | G10: 0.039558466 | H10: 0.08899775 | I10: 0.040705374 | J10: 0.040872502 | K10: 0.031878304 | L10: 0.17343243 | M10: 0.25030763 | N10: 0.21740776 | O10: 0.16619418 | P10: 0.192658 | Q10: 0.92062483 | R10: 0.92062483 | S10: 0.92062483
A11: 10 | B11: Maricopa | C11: 235579 | D11: 127492 | E11: 9979.5924 | F11: 0.021076252 | G11: 0.022652689 | H11: 0.044592054 | I11: 0.024951683 | J11: 0.024913855 | K11: 0.039933247 | L11: 0.11496395 | M11: 0.18159543 | N11: 0.1698216 | O11: 0.19003756 | P11: 0.34358146 | Q11: 1.209315 | R11: 1.209315 | S11: 1.209315
A12: 11 | B12: Maricopa | C12: 237844 | D12: 143724 | E12: 21846.939 | F12: 0.046139317 | G12: 0.047583863 | H12: 0.083216473 | I12: 0.04757338 | J12: 0.049680737 | K12: 0.040143628 | L12: 0.20006544 | M12: 0.20851643 | N12: 0.21626054 | O12: 0.17096603 | P12: 0.20419157 | Q12: 0.93897627 | R12: 0.93897627 | S12: 0.93897627
A13: 12 | B13: Maricopa | C13: 238923 | D13: 155532 | E13: 8755.0651 | F13: 0.018490129 | G13: 0.017851304 | H13: 0.14172159 | I13: 0.019450538 | J13: 0.018848944 | K13: 0.033104981 | L13: 0.13161292 | M13: 0.23349677 | N13: 0.24000039 | O13: 0.18508717 | P13: 0.20980275 | Q13: 0.97694191 | R13: 0.97694191 | S13: 0.97694191
... A31: 30 | B31: Mohave | C31: 237999 | D31: 118280 | E31: 17491.784 | F31: 0.036941512 | G31: 0.039130111 | H31: 0.058381576 | I31: 0.039516824 | J31: 0.038079742 | K31: 0.031560958 | L31: 0.10035761 | M31: 0.17519028 | N31: 0.1699825 | O31: 0.19337902 | P31: 0.36109058 | Q31: 1.2459929 | R31: 1.2459929 | S31: 1.2459929
A33: Total | C33: =SUM(C2:C31) | D33: =SUM(D2:D31) | E33: =SUM(E2:E31) | F33: =SUM(F2:F31) | G33: =SUM(G2:G31) | I33: =SUM(I2:I31) | J33: =SUM(J2:J31) | K33: =SUM(K2:K31)
A35: Keys: ACS 2020-2024 5-year tract tables (C27007, B27010, B18135, B27020, B05006, B27003, B27001) distributed to 2020 census blocks by population and summed to 2022 legislative districts; expansion-adult key = adults 19-64 with Medicaid, excluding Medicare dual-eligibles and adults reporting a disability, calibrated to AHCCCS expansion enrollment by congressional district (Jan 2025); all-ages and adult keys calibrated to AHCCCS enrollment by county (Aug 2026). AIAN share from 2020 Census P3 (AIAN alone, 18+) with the adult Medicaid rate of AIAN-majority tracts (40.4%). Death-rate factor = district deaths per uninsured relative to the statewide rate; it reflects only the district's age profile of adults with public coverage (older = higher).

Sheet Calibration
A1: Congressional district (118th) | B1: ACS-based expansion-adult key (uncalibrated) | C1: AHCCCS expansion enrollment, Jan 1 2025 (Prop 204 + ACA adults) | D1: ACS share | E1: AHCCCS share | F1: Calibration factor
A2: AZ-1 | B2: 32639.769 | C2: 38581 | D2: =B2/SUM($B$2:$B$10) | E2: =C2/SUM($C$2:$C$10) | F2: =E2/D2
